Workbook
Name 반명단: 반설정!$A$4:$A$18
Name 학생명단: 상담데이터입력!$A$3:$A$502

Sheet 사용안내
A1: SYNK 상담 데이터 시트 v18 — 사용 안내
A3: ■ 데이터 흐름 (하나만 기억하세요)
A4: 학생이 구글폼 작성(오프라인이면 상담지 → 폼 대리 입력) → 이 시트에 자동 기록 → 앱(profiles)으로 동기화
A5: 자유서술(다짐·기대·이전학원·취미·선호작품 등)은 시트가 아니라 노션 케어노트에 — 끝나면 BA열 "입력완료"
A7: ■ 🚫 절대 규칙 2가지 (학생ID 보호)
A8: 1. 행 삭제 금지 — 퇴소는 수강·납입 탭에서 퇴소일만 입력
A9: 2. 정렬 금지 — 필터만 사용 (ID·조회 수식이 행 위치 기반입니다)
A10: ※ 구글시트 이관 후에는 Claude가 만든 자동 ID 발급기(불변값)로 교체 예정 → 그때부터 걱정 없음
A12: ■ 반 이름 (v18 신체계)
A13: 트랙+시간: 메인11 · 집중14 · 심화18 · 주말메인11 … — 반 추가·수정은 [반·설정] 탭 한 곳에서만
A15: ■ 입력 팁
A16: 드롭다운 = 클릭 선택(오타 방지) · 코랄색 헤더 6개 = 대시보드 집계 항목 · 나이/ID/위험신호는 자동
... A28: 나이 자동 · 취업비자준비 선택지 · 학습시간 드롭다운 · 반·설정 탭 신설 · 대시보드 슬림(케어는 앱 담당)

Sheet 대시보드
B2: 🎛 SYNK LAB 경영 대시보드
B3: 입력하면 자동 집계 · 케어(위험·임박)는 앱과 주간 리포트가 담당합니다
B5: 핵심 지표
B6: 현재 재원생 | C6: 이달 신규 | D6: 이달 퇴소 | E6: 순증감 | F6: 누적 퇴소 | G6: 이탈률
B7: =COUNTIF(수강납입!K5:K504,"재원중") -> 0 | C7: =SUMPRODUCT((상담데이터입력!$A$3:$A$502<>"")*(TEXT(상담데이터입력!$C$3:$C$502,"yyyy-mm")=TEXT(TODAY(),"yyyy-mm"))) -> 0 | D7: =SUMPRODUCT((수강납입!$H$5:$H$504<>"")*(TEXT(수강납입!$H$5:$H$504,"yyyy-mm")=TEXT(TODAY(),"yyyy-mm"))) -> 0 | E7: =C7-D7 -> 0 | F7: =COUNTIF(수강납입!K5:K504,"퇴소") -> 0 | G7: =IF(B7+F7=0,"-",TEXT(F7/(B7+F7),"0.0%")) -> -
B9: 매출 · 수납 (수강·납입 시트 연동)
B10: 예상 월매출 (MNT) | D10: 🔴 미납 인원 | E10: 미납액 (MNT) | F10: → 명단은 수강·납입 탭의 빨간 행
B11: =SUMIFS(수강납입!E5:E504,수강납입!K5:K504,"재원중") -> 0 | D11: =SUMPRODUCT((수강납입!$K$5:$K$504="재원중")*(수강납입!$J$5:$J$504<>"")*(수강납입!$J$5:$J$504<TODAY())) -> 0 | E11: =SUMPRODUCT((수강납입!$K$5:$K$504="재원중")*(수강납입!$J$5:$J$504<>"")*(수강납입!$J$5:$J$504<TODAY())*수강납입!$E$5:$E$504) -> 0
B13: 분포
B14: TOPIK 목표 | E14: 한국어 수준 | H14: 진학 시기
B15: 1~2급 | C15: =COUNTIF(상담데이터입력!$W$3:$W$502,B15) -> 0 | E15: 완전초보 | F15: =COUNTIF(상담데이터입력!$S$3:$S$502,E15) -> 0 | H15: 올해 | I15: =COUNTIF(상담데이터입력!$Y$3:$Y$502,H15) -> 0
B16: 3~4급 | C16: =COUNTIF(상담데이터입력!$W$3:$W$502,B16) -> 0 | E16: 기초 | F16: =COUNTIF(상담데이터입력!$S$3:$S$502,E16) -> 0 | H16: 내년 | I16: =COUNTIF(상담데이터입력!$Y$3:$Y$502,H16) -> 0
B17: 5~6급 | C17: =COUNTIF(상담데이터입력!$W$3:$W$502,B17) -> 0 | E17: 초중급 | F17: =COUNTIF(상담데이터입력!$S$3:$S$502,E17) -> 0 | H17: 기타/미정 | I17: =COUNTIF(상담데이터입력!$Y$3:$Y$502,H17) -> 0
E18: 중급 | F18: =COUNTIF(상담데이터입력!$S$3:$S$502,E18) -> 0
E19: 고급 | F19: =COUNTIF(상담데이터입력!$S$3:$S$502,E19) -> 0
B21: 🪑 반별 재원 / 정원 / 여석 (반·설정 연동)
B22: 반 | C22: 정원 | D22: 재원 | E22: 여석 | F22: 재원 시각화 (1칸=2명)
B23: =반설정!A4 -> 정규반1 | C23: =반설정!D4 -> 20 | D23: =COUNTIFS(수강납입!$C$5:$C$504,$B23,수강납입!$K$5:$K$504,"재원중") -> 0 | E23: =C23-D23 -> 20 | F23: =IF(B23="","",REPT("▮",ROUND(D23/2,0))&REPT("▯",ROUNDUP(E23/2,0))) -> ▯▯▯▯▯▯▯▯▯▯
B24: =반설정!A5 -> 정규반2 | C24: =반설정!D5 -> 20 | D24: =COUNTIFS(수강납입!$C$5:$C$504,$B24,수강납입!$K$5:$K$504,"재원중") -> 0 | E24: =C24-D24 -> 20 | F24: =IF(B24="","",REPT("▮",ROUND(D24/2,0))&REPT("▯",ROUNDUP(E24/2,0))) -> ▯▯▯▯▯▯▯▯▯▯
B25: =반설정!A6 -> 정규반3 | C25: =반설정!D6 -> 20 | D25: =COUNTIFS(수강납입!$C$5:$C$504,$B25,수강납입!$K$5:$K$504,"재원중") -> 0 | E25: =C25-D25 -> 20 | F25: =IF(B25="","",REPT("▮",ROUND(D25/2,0))&REPT("▯",ROUNDUP(E25/2,0))) -> ▯▯▯▯▯▯▯▯▯▯
B26: =반설정!A7 -> 정규반4 | C26: =반설정!D7 -> 20 | D26: =COUNTIFS(수강납입!$C$5:$C$504,$B26,수강납입!$K$5:$K$504,"재원중") -> 0 | E26: =C26-D26 -> 20 | F26: =IF(B26="","",REPT("▮",ROUND(D26/2,0))&REPT("▯",ROUNDUP(E26/2,0))) -> ▯▯▯▯▯▯▯▯▯▯
B27: =반설정!A8 -> 집중반1 | C27: =반설정!D8 -> 10 | D27: =COUNTIFS(수강납입!$C$5:$C$504,$B27,수강납입!$K$5:$K$504,"재원중") -> 0 | E27: =C27-D27 -> 10 | F27: =IF(B27="","",REPT("▮",ROUND(D27/2,0))&REPT("▯",ROUNDUP(E27/2,0))) -> ▯▯▯▯▯
B28: =반설정!A9 -> 집중반2 | C28: =반설정!D9 -> 10 | D28: =COUNTIFS(수강납입!$C$5:$C$504,$B28,수강납입!$K$5:$K$504,"재원중") -> 0 | E28: =C28-D28 -> 10 | F28: =IF(B28="","",REPT("▮",ROUND(D28/2,0))&REPT("▯",ROUNDUP(E28/2,0))) -> ▯▯▯▯▯
B29: =반설정!A10 -> 집중반3 | C29: =반설정!D10 -> 10 | D29: =COUNTIFS(수강납입!$C$5:$C$504,$B29,수강납입!$K$5:$K$504,"재원중") -> 0 | E29: =C29-D29 -> 10 | F29: =IF(B29="","",REPT("▮",ROUND(D29/2,0))&REPT("▯",ROUNDUP(E29/2,0))) -> ▯▯▯▯▯
B30: =반설정!A11 -> 집중반4 | C30: =반설정!D11 -> 10 | D30: =COUNTIFS(수강납입!$C$5:$C$504,$B30,수강납입!$K$5:$K$504,"재원중") -> 0 | E30: =C30-D30 -> 10 | F30: =IF(B30="","",REPT("▮",ROUND(D30/2,0))&REPT("▯",ROUNDUP(E30/2,0))) -> ▯▯▯▯▯
B31: =반설정!A12 -> 집중반5 | C31: =반설정!D12 -> 10 | D31: =COUNTIFS(수강납입!$C$5:$C$504,$B31,수강납입!$K$5:$K$504,"재원중") -> 0 | E31: =C31-D31 -> 10 | F31: =IF(B31="","",REPT("▮",ROUND(D31/2,0))&REPT("▯",ROUNDUP(E31/2,0))) -> ▯▯▯▯▯
B32: =반설정!A13 -> 집중반6 | C32: =반설정!D13 -> 10 | D32: =COUNTIFS(수강납입!$C$5:$C$504,$B32,수강납입!$K$5:$K$504,"재원중") -> 0 | E32: =C32-D32 -> 10 | F32: =IF(B32="","",REPT("▮",ROUND(D32/2,0))&REPT("▯",ROUNDUP(E32/2,0))) -> ▯▯▯▯▯
B33: =반설정!A14 -> 주말정규반1 | C33: =반설정!D14 -> 20 | D33: =COUNTIFS(수강납입!$C$5:$C$504,$B33,수강납입!$K$5:$K$504,"재원중") -> 0 | E33: =C33-D33 -> 20 | F33: =IF(B33="","",REPT("▮",ROUND(D33/2,0))&REPT("▯",ROUNDUP(E33/2,0))) -> ▯▯▯▯▯▯▯▯▯▯
B34: =반설정!A15 -> 주말정규반2 | C34: =반설정!D15 -> 20 | D34: =COUNTIFS(수강납입!$C$5:$C$504,$B34,수강납입!$K$5:$K$504,"재원중") -> 0 | E34: =C34-D34 -> 20 | F34: =IF(B34="","",REPT("▮",ROUND(D34/2,0))&REPT("▯",ROUNDUP(E34/2,0))) -> ▯▯▯▯▯▯▯▯▯▯
... B37: =반설정!A18 -> 주말집중반3 | C37: =반설정!D18 -> 10 | D37: =COUNTIFS(수강납입!$C$5:$C$504,$B37,수강납입!$K$5:$K$504,"재원중") -> 0 | E37: =C37-D37 -> 10 | F37: =IF(B37="","",REPT("▮",ROUND(D37/2,0))&REPT("▯",ROUNDUP(E37/2,0))) -> ▯▯▯▯▯
B39: 📊 등록자 인사이트 (드롭다운 자동 집계)
B40: 인지채널 | D40: 학습배경 | F40: 관심 K분야 | H40: 핵심 가치관 | J40: 대표 강점 | L40: 🇬🇧 영어수업 희망
B41: 릴스 | C41: =COUNTIF(상담데이터입력!$BE$3:$BE$502,B41) -> 0 | D41: 독학 | E41: =COUNTIF(상담데이터입력!$U$3:$U$502,D41) -> 0 | F41: KPOP | G41: =COUNTIF(상담데이터입력!$AY$3:$AY$502,F41) -> 0 | H41: 안정성 | I41: =COUNTIF(상담데이터입력!$AJ$3:$AJ$502,H41) -> 0 | J41: 리더십 | K41: =COUNTIF(상담데이터입력!$AX$3:$AX$502,J41) -> 0 | L41: 매우희망 | M41: =COUNTIF(상담데이터입력!$BD$3:$BD$502,L41) -> 0
B42: 지인추천 | C42: =COUNTIF(상담데이터입력!$BE$3:$BE$502,B42) -> 0 | D42: 학원 | E42: =COUNTIF(상담데이터입력!$U$3:$U$502,D42) -> 0 | F42: 드라마 | G42: =COUNTIF(상담데이터입력!$AY$3:$AY$502,F42) -> 0 | H42: 고수입 | I42: =COUNTIF(상담데이터입력!$AJ$3:$AJ$502,H42) -> 0 | J42: 분석력 | K42: =COUNTIF(상담데이터입력!$AX$3:$AX$502,J42) -> 0 | L42: 보통 | M42: =COUNTIF(상담데이터입력!$BD$3:$BD$502,L42) -> 0
B43: 광고 | C43: =COUNTIF(상담데이터입력!$BE$3:$BE$502,B43) -> 0 | D43: 온라인 | E43: =COUNTIF(상담데이터입력!$U$3:$U$502,D43) -> 0 | F43: 뷰티패션 | G43: =COUNTIF(상담데이터입력!$AY$3:$AY$502,F43) -> 0 | H43: 보람성취 | I43: =COUNTIF(상담데이터입력!$AJ$3:$AJ$502,H43) -> 0 | J43: 예술감각 | K43: =COUNTIF(상담데이터입력!$AX$3:$AX$502,J43) -> 0 | L43: 없음 | M43: =COUNTIF(상담데이터입력!$BD$3:$BD$502,L43) -> 0
B44: 기타 | C44: =COUNTIF(상담데이터입력!$BE$3:$BE$502,B44) -> 0 | D44: K콘텐츠 | E44: =COUNTIF(상담데이터입력!$U$3:$U$502,D44) -> 0 | F44: 음식 | G44: =COUNTIF(상담데이터입력!$AY$3:$AY$502,F44) -> 0 | H44: 워라밸 | I44: =COUNTIF(상담데이터입력!$AJ$3:$AJ$502,H44) -> 0 | J44: 추진력 | K44: =COUNTIF(상담데이터입력!$AX$3:$AX$502,J44) -> 0
J45: 창의성 | K45: =COUNTIF(상담데이터입력!$AX$3:$AX$502,J45) -> 0
J46: 소통 | K46: =COUNTIF(상담데이터입력!$AX$3:$AX$502,J46) -> 0
J47: 꼼꼼함 | K47: =COUNTIF(상담데이터입력!$AX$3:$AX$502,J47) -> 0
J48: 기타 | K48: =COUNTIF(상담데이터입력!$AX$3:$AX$502,J48) -> 0
...

Sheet 학생카드
B2: 학생 카드 조회
B3: 아래 노란 칸에서 학생 이름을 고르면 정보가 자동으로 채워집니다.
B5: 학생 선택 →
B7: =IF($C$5="","(학생을 선택하세요)",$C$5 & " / " & IFERROR(INDEX(상담데이터입력!B3:B502,MATCH($C$5,상담데이터입력!A3:A502,0)),"")) -> (학생을 선택하세요)
B8: =IF($C$5="","",IFERROR(INDEX(상담데이터입력!BI3:BI502,MATCH($C$5,상담데이터입력!A3:A502,0)),""))
B10: 기본 정보
B11: 등록일 | C11: =IF($C$5="","",IFERROR(INDEX(상담데이터입력!C3:C502,MATCH($C$5,상담데이터입력!A3:A502,0)),"")) | D11: 대학진학시기 | E11: =IF($C$5="","",IFERROR(INDEX(상담데이터입력!Z3:Z502,MATCH($C$5,상담데이터입력!A3:A502,0)),""))
B12: 생년월일 | C12: =IF($C$5="","",IFERROR(INDEX(상담데이터입력!E3:E502,MATCH($C$5,상담데이터입력!A3:A502,0)),"")) | D12: 거주지역 | E12: =IF($C$5="","",IFERROR(INDEX(상담데이터입력!J3:J502,MATCH($C$5,상담데이터입력!A3:A502,0)),""))
B13: 성별 | C13: =IF($C$5="","",IFERROR(INDEX(상담데이터입력!G3:G502,MATCH($C$5,상담데이터입력!A3:A502,0)),"")) | D13: 최종학력 | E13: =IF($C$5="","",IFERROR(INDEX(상담데이터입력!K3:K502,MATCH($C$5,상담데이터입력!A3:A502,0)),""))
B14: 연락처 | C14: =IF($C$5="","",IFERROR(INDEX(상담데이터입력!H3:H502,MATCH($C$5,상담데이터입력!A3:A502,0)),"")) | D14: 이메일 | E14: =IF($C$5="","",IFERROR(INDEX(상담데이터입력!I3:I502,MATCH($C$5,상담데이터입력!A3:A502,0)),""))
B15: SNS ID | C15: =IF($C$5="","",IFERROR(INDEX(상담데이터입력!I3:I502,MATCH($C$5,상담데이터입력!A3:A502,0)),"")) | D15: 담당크루 | E15: =IF($C$5="","",IFERROR(INDEX(상담데이터입력!D3:D502,MATCH($C$5,상담데이터입력!A3:A502,0)),""))
B17: 보호자
B18: 보호자명 | C18: =IF($C$5="","",IFERROR(INDEX(상담데이터입력!M3:M502,MATCH($C$5,상담데이터입력!A3:A502,0)),"")) | D18: 관계 | E18: =IF($C$5="","",IFERROR(INDEX(상담데이터입력!M3:M502,MATCH($C$5,상담데이터입력!A3:A502,0)),""))
B19: 보호자연락처 | C19: =IF($C$5="","",IFERROR(INDEX(상담데이터입력!O3:O502,MATCH($C$5,상담데이터입력!A3:A502,0)),"")) | D19: 가족지지 | E19: =IF($C$5="","",IFERROR(INDEX(상담데이터입력!AT3:AT502,MATCH($C$5,상담데이터입력!A3:A502,0)),""))
B21: 한국어 / 어학
B22: 한국어수준 | C22: =IF($C$5="","",IFERROR(INDEX(상담데이터입력!S3:S502,MATCH($C$5,상담데이터입력!A3:A502,0)),"")) | D22: TOPIK급수 | E22: =IF($C$5="","",IFERROR(INDEX(상담데이터입력!O3:O502,MATCH($C$5,상담데이터입력!A3:A502,0)),""))
B23: TOPIK점수 | C23: =IF($C$5="","",IFERROR(INDEX(상담데이터입력!Q3:Q502,MATCH($C$5,상담데이터입력!A3:A502,0)),"")) | D23: TOPIK목표 | E23: =IF($C$5="","",IFERROR(INDEX(상담데이터입력!W3:W502,MATCH($C$5,상담데이터입력!A3:A502,0)),""))
B24: TOPIK목표기한 | C24: =IF($C$5="","",IFERROR(INDEX(상담데이터입력!X3:X502,MATCH($C$5,상담데이터입력!A3:A502,0)),"")) | D24: 기타인증서 | E24: =IF($C$5="","",IFERROR(INDEX(상담데이터입력!Q3:Q502,MATCH($C$5,상담데이터입력!A3:A502,0)),""))
B25: 영어(점수/회화) | C25: =IF($C$5="","",IFERROR(INDEX(상담데이터입력!T3:T502,MATCH($C$5,상담데이터입력!A3:A502,0)),"")) | D25: 주_핵심비전 | E25: =IF($C$5="","",IFERROR(INDEX(상담데이터입력!$CK$3:$CK$502,MATCH($C$5,상담데이터입력!$A$3:$A$502,0)),""))
B27: 목표 / 진로
B28: 핵심비전 | C28: =IF($C$5="","",IFERROR(INDEX(상담데이터입력!V3:V502,MATCH($C$5,상담데이터입력!A3:A502,0)),"")) | D28: 졸업후진로 | E28: =IF($C$5="","",IFERROR(INDEX(상담데이터입력!AJ3:AJ502,MATCH($C$5,상담데이터입력!A3:A502,0)),""))
B29: 희망진학과정 | C29: =IF($C$5="","",IFERROR(INDEX(상담데이터입력!AD3:AD502,MATCH($C$5,상담데이터입력!A3:A502,0)),"")) | D29: 희망진학지역 | E29: =IF($C$5="","",IFERROR(INDEX(상담데이터입력!AF3:AF502,MATCH($C$5,상담데이터입력!A3:A502,0)),""))
B30: 현재직업 | C30: =IF($C$5="","",IFERROR(INDEX(상담데이터입력!AF3:AF502,MATCH($C$5,상담데이터입력!A3:A502,0)),"")) | D30: 목표달성시기 | E30: =IF($C$5="","",IFERROR(INDEX(상담데이터입력!AI3:AI502,MATCH($C$5,상담데이터입력!A3:A502,0)),""))
B31: 학습가능시간 | C31: =IF($C$5="","",IFERROR(INDEX(상담데이터입력!AG3:AG502,MATCH($C$5,상담데이터입력!A3:A502,0)),"")) | D31: 유학예산 | E31: =IF($C$5="","",IFERROR(INDEX(상담데이터입력!AR3:AR502,MATCH($C$5,상담데이터입력!A3:A502,0)),""))
B32: 학비조달주체 | C32: =IF($C$5="","",IFERROR(INDEX(상담데이터입력!AR3:AR502,MATCH($C$5,상담데이터입력!A3:A502,0)),"")) | D32: 핵심가치관(주) | E32: =IF($C$5="","",IFERROR(INDEX(상담데이터입력!$CJ$3:$CJ$502,MATCH($C$5,상담데이터입력!$A$3:$A$502,0)),""))
B34: 지망 대학 / 전공
B35: 지망대학 1 | C35: =IF($C$5="","",IFERROR(INDEX(상담데이터입력!AK3:AK502,MATCH($C$5,상담데이터입력!A3:A502,0)),"")) | D35: 지망전공 1 | E35: =IF($C$5="","",IFERROR(INDEX(상담데이터입력!AO3:AO502,MATCH($C$5,상담데이터입력!A3:A502,0)),""))
B36: 지망대학 2 | C36: =IF($C$5="","",IFERROR(INDEX(상담데이터입력!AL3:AL502,MATCH($C$5,상담데이터입력!A3:A502,0)),""))
B37: 지망대학 3 | C37: =IF($C$5="","",IFERROR(INDEX(상담데이터입력!AM3:AM502,MATCH($C$5,상담데이터입력!A3:A502,0)),""))
B39: 비자 / 방문
B40: 한국방문경험 | C40: =IF($C$5="","",IFERROR(INDEX(상담데이터입력!Z3:Z502,MATCH($C$5,상담데이터입력!A3:A502,0)),"")) | D40: 비자신청이력 | E40: =IF($C$5="","",IFERROR(INDEX(상담데이터입력!AB3:AB502,MATCH($C$5,상담데이터입력!A3:A502,0)),""))
B41: 거절비자종류 | C41: =IF($C$5="","",IFERROR(INDEX(상담데이터입력!AB3:AB502,MATCH($C$5,상담데이터입력!A3:A502,0)),"")) | D41: 가족한국체류 | E41: =IF($C$5="","",IFERROR(INDEX(상담데이터입력!AD3:AD502,MATCH($C$5,상담데이터입력!A3:A502,0)),""))
B43: 성향 / 학습 스타일
B44: 성격유형 | C44: =IF($C$5="","",IFERROR(INDEX(상담데이터입력!AT3:AT502,MATCH($C$5,상담데이터입력!A3:A502,0)),"")) | D44: 대표강점(주) | E44: =IF($C$5="","",IFERROR(INDEX(상담데이터입력!$CI$3:$CI$502,MATCH($C$5,상담데이터입력!$A$3:$A$502,0)),""))
B45: 학습_집중 | C45: =IF($C$5="","",IFERROR(INDEX(상담데이터입력!AU3:AU502,MATCH($C$5,상담데이터입력!A3:A502,0)),"")) | D45: 학습_방식 | E45: =IF($C$5="","",IFERROR(INDEX(상담데이터입력!AW3:AW502,MATCH($C$5,상담데이터입력!A3:A502,0)),""))
B46: 학습_태도 | C46: =IF($C$5="","",IFERROR(INDEX(상담데이터입력!AW3:AW502,MATCH($C$5,상담데이터입력!A3:A502,0)),"")) | D46: SYNK인지경로 | E46: =IF($C$5="","",IFERROR(INDEX(상담데이터입력!BF3:BF502,MATCH($C$5,상담데이터입력!A3:A502,0)),""))
B48: K컬처 관심
B49: 관심한국문화 | C49: =IF($C$5="","",IFERROR(INDEX(상담데이터입력!AY3:AY502,MATCH($C$5,상담데이터입력!A3:A502,0)),"")) | D49: 선호KPOP/드라마 | E49: =IF($C$5="","",IFERROR(INDEX(상담데이터입력!BA3:BA502,MATCH($C$5,상담데이터입력!A3:A502,0)),""))
B50: KPOP댄스희망 | C50: =IF($C$5="","",IFERROR(INDEX(상담데이터입력!AZ3:AZ502,MATCH($C$5,상담데이터입력!A3:A502,0)),"")) | D50: 보컬트레이닝 | E50: =IF($C$5="","",IFERROR(INDEX(상담데이터입력!BC3:BC502,MATCH($C$5,상담데이터입력!A3:A502,0)),""))
B51: 연기체험 | C51: =IF($C$5="","",IFERROR(INDEX(상담데이터입력!BB3:BB502,MATCH($C$5,상담데이터입력!A3:A502,0)),"")) | D51: K뷰티메이크업 | E51: =IF($C$5="","",IFERROR(INDEX(상담데이터입력!BE3:BE502,MATCH($C$5,상담데이터입력!A3:A502,0)),""))
...

Sheet 반별조회
B2: 반별 학생 조회
B3: 반을 고르면 그 반 담당 학생만 아래에 자동으로 표시됩니다. (조회 전용 — 수정은 상담데이터입력 시트에서)
B5: 반 선택 → | F5: 인원 | G5: =IF($C$5="",0,COUNTIF(상담데이터입력!D3:D502,$C$5)) -> 0
B7: 이름(한) | C7: 이름(몽) | D7: 연락처 | E7: 한국어수준 | F7: TOPIK목표 | G7: 진학시기 | H7: 출결/비고 | I7: ⚠위험신호
B8: =IFERROR(INDEX(상담데이터입력!A3:A502,MATCH(1,상담데이터입력!$BJ$3:$BJ$502,0)),"") | C8: =IF($B8="","",IFERROR(INDEX(상담데이터입력!B3:B502,MATCH($B8,상담데이터입력!A3:A502,0)),"")) | D8: =IF($B8="","",IFERROR(INDEX(상담데이터입력!H3:H502,MATCH($B8,상담데이터입력!A3:A502,0)),"")) | E8: =IF($B8="","",IFERROR(INDEX(상담데이터입력!S3:S502,MATCH($B8,상담데이터입력!A3:A502,0)),"")) | F8: =IF($B8="","",IFERROR(INDEX(상담데이터입력!W3:W502,MATCH($B8,상담데이터입력!A3:A502,0)),"")) | G8: =IF($B8="","",IFERROR(INDEX(상담데이터입력!Y3:Y502,MATCH($B8,상담데이터입력!A3:A502,0)),"")) | H8: =IF($B8="","",IFERROR(INDEX(상담데이터입력!BG3:BG502,MATCH($B8,상담데이터입력!A3:A502,0)),"")) | I8: =IF($B8="","",IFERROR(INDEX(상담데이터입력!BI3:BI502,MATCH($B8,상담데이터입력!A3:A502,0)),""))
B9: =IFERROR(INDEX(상담데이터입력!A3:A502,MATCH(2,상담데이터입력!$BJ$3:$BJ$502,0)),"") | C9: =IF($B9="","",IFERROR(INDEX(상담데이터입력!B3:B502,MATCH($B9,상담데이터입력!A3:A502,0)),"")) | D9: =IF($B9="","",IFERROR(INDEX(상담데이터입력!H3:H502,MATCH($B9,상담데이터입력!A3:A502,0)),"")) | E9: =IF($B9="","",IFERROR(INDEX(상담데이터입력!S3:S502,MATCH($B9,상담데이터입력!A3:A502,0)),"")) | F9: =IF($B9="","",IFERROR(INDEX(상담데이터입력!W3:W502,MATCH($B9,상담데이터입력!A3:A502,0)),"")) | G9: =IF($B9="","",IFERROR(INDEX(상담데이터입력!Y3:Y502,MATCH($B9,상담데이터입력!A3:A502,0)),"")) | H9: =IF($B9="","",IFERROR(INDEX(상담데이터입력!BG3:BG502,MATCH($B9,상담데이터입력!A3:A502,0)),"")) | I9: =IF($B9="","",IFERROR(INDEX(상담데이터입력!BI3:BI502,MATCH($B9,상담데이터입력!A3:A502,0)),""))
B10: =IFERROR(INDEX(상담데이터입력!A3:A502,MATCH(3,상담데이터입력!$BJ$3:$BJ$502,0)),"") | C10: =IF($B10="","",IFERROR(INDEX(상담데이터입력!B3:B502,MATCH($B10,상담데이터입력!A3:A502,0)),"")) | D10: =IF($B10="","",IFERROR(INDEX(상담데이터입력!H3:H502,MATCH($B10,상담데이터입력!A3:A502,0)),"")) | E10: =IF($B10="","",IFERROR(INDEX(상담데이터입력!S3:S502,MATCH($B10,상담데이터입력!A3:A502,0)),"")) | F10: =IF($B10="","",IFERROR(INDEX(상담데이터입력!W3:W502,MATCH($B10,상담데이터입력!A3:A502,0)),"")) | G10: =IF($B10="","",IFERROR(INDEX(상담데이터입력!Y3:Y502,MATCH($B10,상담데이터입력!A3:A502,0)),"")) | H10: =IF($B10="","",IFERROR(INDEX(상담데이터입력!BG3:BG502,MATCH($B10,상담데이터입력!A3:A502,0)),"")) | I10: =IF($B10="","",IFERROR(INDEX(상담데이터입력!BI3:BI502,MATCH($B10,상담데이터입력!A3:A502,0)),""))
B11: =IFERROR(INDEX(상담데이터입력!A3:A502,MATCH(4,상담데이터입력!$BJ$3:$BJ$502,0)),"") | C11: =IF($B11="","",IFERROR(INDEX(상담데이터입력!B3:B502,MATCH($B11,상담데이터입력!A3:A502,0)),"")) | D11: =IF($B11="","",IFERROR(INDEX(상담데이터입력!H3:H502,MATCH($B11,상담데이터입력!A3:A502,0)),"")) | E11: =IF($B11="","",IFERROR(INDEX(상담데이터입력!S3:S502,MATCH($B11,상담데이터입력!A3:A502,0)),"")) | F11: =IF($B11="","",IFERROR(INDEX(상담데이터입력!W3:W502,MATCH($B11,상담데이터입력!A3:A502,0)),"")) | G11: =IF($B11="","",IFERROR(INDEX(상담데이터입력!Y3:Y502,MATCH($B11,상담데이터입력!A3:A502,0)),"")) | H11: =IF($B11="","",IFERROR(INDEX(상담데이터입력!BG3:BG502,MATCH($B11,상담데이터입력!A3:A502,0)),"")) | I11: =IF($B11="","",IFERROR(INDEX(상담데이터입력!BI3:BI502,MATCH($B11,상담데이터입력!A3:A502,0)),""))
B12: =IFERROR(INDEX(상담데이터입력!A3:A502,MATCH(5,상담데이터입력!$BJ$3:$BJ$502,0)),"") | C12: =IF($B12="","",IFERROR(INDEX(상담데이터입력!B3:B502,MATCH($B12,상담데이터입력!A3:A502,0)),"")) | D12: =IF($B12="","",IFERROR(INDEX(상담데이터입력!H3:H502,MATCH($B12,상담데이터입력!A3:A502,0)),"")) | E12: =IF($B12="","",IFERROR(INDEX(상담데이터입력!S3:S502,MATCH($B12,상담데이터입력!A3:A502,0)),"")) | F12: =IF($B12="","",IFERROR(INDEX(상담데이터입력!W3:W502,MATCH($B12,상담데이터입력!A3:A502,0)),"")) | G12: =IF($B12="","",IFERROR(INDEX(상담데이터입력!Y3:Y502,MATCH($B12,상담데이터입력!A3:A502,0)),"")) | H12: =IF($B12="","",IFERROR(INDEX(상담데이터입력!BG3:BG502,MATCH($B12,상담데이터입력!A3:A502,0)),"")) | I12: =IF($B12="","",IFERROR(INDEX(상담데이터입력!BI3:BI502,MATCH($B12,상담데이터입력!A3:A502,0)),""))
B13: =IFERROR(INDEX(상담데이터입력!A3:A502,MATCH(6,상담데이터입력!$BJ$3:$BJ$502,0)),"") | C13: =IF($B13="","",IFERROR(INDEX(상담데이터입력!B3:B502,MATCH($B13,상담데이터입력!A3:A502,0)),"")) | D13: =IF($B13="","",IFERROR(INDEX(상담데이터입력!H3:H502,MATCH($B13,상담데이터입력!A3:A502,0)),"")) | E13: =IF($B13="","",IFERROR(INDEX(상담데이터입력!S3:S502,MATCH($B13,상담데이터입력!A3:A502,0)),"")) | F13: =IF($B13="","",IFERROR(INDEX(상담데이터입력!W3:W502,MATCH($B13,상담데이터입력!A3:A502,0)),"")) | G13: =IF($B13="","",IFERROR(INDEX(상담데이터입력!Y3:Y502,MATCH($B13,상담데이터입력!A3:A502,0)),"")) | H13: =IF($B13="","",IFERROR(INDEX(상담데이터입력!BG3:BG502,MATCH($B13,상담데이터입력!A3:A502,0)),"")) | I13: =IF($B13="","",IFERROR(INDEX(상담데이터입력!BI3:BI502,MATCH($B13,상담데이터입력!A3:A502,0)),""))
B14: =IFERROR(INDEX(상담데이터입력!A3:A502,MATCH(7,상담데이터입력!$BJ$3:$BJ$502,0)),"") | C14: =IF($B14="","",IFERROR(INDEX(상담데이터입력!B3:B502,MATCH($B14,상담데이터입력!A3:A502,0)),"")) | D14: =IF($B14="","",IFERROR(INDEX(상담데이터입력!H3:H502,MATCH($B14,상담데이터입력!A3:A502,0)),"")) | E14: =IF($B14="","",IFERROR(INDEX(상담데이터입력!S3:S502,MATCH($B14,상담데이터입력!A3:A502,0)),"")) | F14: =IF($B14="","",IFERROR(INDEX(상담데이터입력!W3:W502,MATCH($B14,상담데이터입력!A3:A502,0)),"")) | G14: =IF($B14="","",IFERROR(INDEX(상담데이터입력!Y3:Y502,MATCH($B14,상담데이터입력!A3:A502,0)),"")) | H14: =IF($B14="","",IFERROR(INDEX(상담데이터입력!BG3:BG502,MATCH($B14,상담데이터입력!A3:A502,0)),"")) | I14: =IF($B14="","",IFERROR(INDEX(상담데이터입력!BI3:BI502,MATCH($B14,상담데이터입력!A3:A502,0)),""))
B15: =IFERROR(INDEX(상담데이터입력!A3:A502,MATCH(8,상담데이터입력!$BJ$3:$BJ$502,0)),"") | C15: =IF($B15="","",IFERROR(INDEX(상담데이터입력!B3:B502,MATCH($B15,상담데이터입력!A3:A502,0)),"")) | D15: =IF($B15="","",IFERROR(INDEX(상담데이터입력!H3:H502,MATCH($B15,상담데이터입력!A3:A502,0)),"")) | E15: =IF($B15="","",IFERROR(INDEX(상담데이터입력!S3:S502,MATCH($B15,상담데이터입력!A3:A502,0)),"")) | F15: =IF($B15="","",IFERROR(INDEX(상담데이터입력!W3:W502,MATCH($B15,상담데이터입력!A3:A502,0)),"")) | G15: =IF($B15="","",IFERROR(INDEX(상담데이터입력!Y3:Y502,MATCH($B15,상담데이터입력!A3:A502,0)),"")) | H15: =IF($B15="","",IFERROR(INDEX(상담데이터입력!BG3:BG502,MATCH($B15,상담데이터입력!A3:A502,0)),"")) | I15: =IF($B15="","",IFERROR(INDEX(상담데이터입력!BI3:BI502,MATCH($B15,상담데이터입력!A3:A502,0)),""))
B16: =IFERROR(INDEX(상담데이터입력!A3:A502,MATCH(9,상담데이터입력!$BJ$3:$BJ$502,0)),"") | C16: =IF($B16="","",IFERROR(INDEX(상담데이터입력!B3:B502,MATCH($B16,상담데이터입력!A3:A502,0)),"")) | D16: =IF($B16="","",IFERROR(INDEX(상담데이터입력!H3:H502,MATCH($B16,상담데이터입력!A3:A502,0)),"")) | E16: =IF($B16="","",IFERROR(INDEX(상담데이터입력!S3:S502,MATCH($B16,상담데이터입력!A3:A502,0)),"")) | F16: =IF($B16="","",IFERROR(INDEX(상담데이터입력!W3:W502,MATCH($B16,상담데이터입력!A3:A502,0)),"")) | G16: =IF($B16="","",IFERROR(INDEX(상담데이터입력!Y3:Y502,MATCH($B16,상담데이터입력!A3:A502,0)),"")) | H16: =IF($B16="","",IFERROR(INDEX(상담데이터입력!BG3:BG502,MATCH($B16,상담데이터입력!A3:A502,0)),"")) | I16: =IF($B16="","",IFERROR(INDEX(상담데이터입력!BI3:BI502,MATCH($B16,상담데이터입력!A3:A502,0)),""))
B17: =IFERROR(INDEX(상담데이터입력!A3:A502,MATCH(10,상담데이터입력!$BJ$3:$BJ$502,0)),"") | C17: =IF($B17="","",IFERROR(INDEX(상담데이터입력!B3:B502,MATCH($B17,상담데이터입력!A3:A502,0)),"")) | D17: =IF($B17="","",IFERROR(INDEX(상담데이터입력!H3:H502,MATCH($B17,상담데이터입력!A3:A502,0)),"")) | E17: =IF($B17="","",IFERROR(INDEX(상담데이터입력!S3:S502,MATCH($B17,상담데이터입력!A3:A502,0)),"")) | F17: =IF($B17="","",IFERROR(INDEX(상담데이터입력!W3:W502,MATCH($B17,상담데이터입력!A3:A502,0)),"")) | G17: =IF($B17="","",IFERROR(INDEX(상담데이터입력!Y3:Y502,MATCH($B17,상담데이터입력!A3:A502,0)),"")) | H17: =IF($B17="","",IFERROR(INDEX(상담데이터입력!BG3:BG502,MATCH($B17,상담데이터입력!A3:A502,0)),"")) | I17: =IF($B17="","",IFERROR(INDEX(상담데이터입력!BI3:BI502,MATCH($B17,상담데이터입력!A3:A502,0)),""))
B18: =IFERROR(INDEX(상담데이터입력!A3:A502,MATCH(11,상담데이터입력!$BJ$3:$BJ$502,0)),"") | C18: =IF($B18="","",IFERROR(INDEX(상담데이터입력!B3:B502,MATCH($B18,상담데이터입력!A3:A502,0)),"")) | D18: =IF($B18="","",IFERROR(INDEX(상담데이터입력!H3:H502,MATCH($B18,상담데이터입력!A3:A502,0)),"")) | E18: =IF($B18="","",IFERROR(INDEX(상담데이터입력!S3:S502,MATCH($B18,상담데이터입력!A3:A502,0)),"")) | F18: =IF($B18="","",IFERROR(INDEX(상담데이터입력!W3:W502,MATCH($B18,상담데이터입력!A3:A502,0)),"")) | G18: =IF($B18="","",IFERROR(INDEX(상담데이터입력!Y3:Y502,MATCH($B18,상담데이터입력!A3:A502,0)),"")) | H18: =IF($B18="","",IFERROR(INDEX(상담데이터입력!BG3:BG502,MATCH($B18,상담데이터입력!A3:A502,0)),"")) | I18: =IF($B18="","",IFERROR(INDEX(상담데이터입력!BI3:BI502,MATCH($B18,상담데이터입력!A3:A502,0)),""))
B19: =IFERROR(INDEX(상담데이터입력!A3:A502,MATCH(12,상담데이터입력!$BJ$3:$BJ$502,0)),"") | C19: =IF($B19="","",IFERROR(INDEX(상담데이터입력!B3:B502,MATCH($B19,상담데이터입력!A3:A502,0)),"")) | D19: =IF($B19="","",IFERROR(INDEX(상담데이터입력!H3:H502,MATCH($B19,상담데이터입력!A3:A502,0)),"")) | E19: =IF($B19="","",IFERROR(INDEX(상담데이터입력!S3:S502,MATCH($B19,상담데이터입력!A3:A502,0)),"")) | F19: =IF($B19="","",IFERROR(INDEX(상담데이터입력!W3:W502,MATCH($B19,상담데이터입력!A3:A502,0)),"")) | G19: =IF($B19="","",IFERROR(INDEX(상담데이터입력!Y3:Y502,MATCH($B19,상담데이터입력!A3:A502,0)),"")) | H19: =IF($B19="","",IFERROR(INDEX(상담데이터입력!BG3:BG502,MATCH($B19,상담데이터입력!A3:A502,0)),"")) | I19: =IF($B19="","",IFERROR(INDEX(상담데이터입력!BI3:BI502,MATCH($B19,상담데이터입력!A3:A502,0)),""))
B20: =IFERROR(INDEX(상담데이터입력!A3:A502,MATCH(13,상담데이터입력!$BJ$3:$BJ$502,0)),"") | C20: =IF($B20="","",IFERROR(INDEX(상담데이터입력!B3:B502,MATCH($B20,상담데이터입력!A3:A502,0)),"")) | D20: =IF($B20="","",IFERROR(INDEX(상담데이터입력!H3:H502,MATCH($B20,상담데이터입력!A3:A502,0)),"")) | E20: =IF($B20="","",IFERROR(INDEX(상담데이터입력!S3:S502,MATCH($B20,상담데이터입력!A3:A502,0)),"")) | F20: =IF($B20="","",IFERROR(INDEX(상담데이터입력!W3:W502,MATCH($B20,상담데이터입력!A3:A502,0)),"")) | G20: =IF($B20="","",IFERROR(INDEX(상담데이터입력!Y3:Y502,MATCH($B20,상담데이터입력!A3:A502,0)),"")) | H20: =IF($B20="","",IFERROR(INDEX(상담데이터입력!BG3:BG502,MATCH($B20,상담데이터입력!A3:A502,0)),"")) | I20: =IF($B20="","",IFERROR(INDEX(상담데이터입력!BI3:BI502,MATCH($B20,상담데이터입력!A3:A502,0)),""))
B21: =IFERROR(INDEX(상담데이터입력!A3:A502,MATCH(14,상담데이터입력!$BJ$3:$BJ$502,0)),"") | C21: =IF($B21="","",IFERROR(INDEX(상담데이터입력!B3:B502,MATCH($B21,상담데이터입력!A3:A502,0)),"")) | D21: =IF($B21="","",IFERROR(INDEX(상담데이터입력!H3:H502,MATCH($B21,상담데이터입력!A3:A502,0)),"")) | E21: =IF($B21="","",IFERROR(INDEX(상담데이터입력!S3:S502,MATCH($B21,상담데이터입력!A3:A502,0)),"")) | F21: =IF($B21="","",IFERROR(INDEX(상담데이터입력!W3:W502,MATCH($B21,상담데이터입력!A3:A502,0)),"")) | G21: =IF($B21="","",IFERROR(INDEX(상담데이터입력!Y3:Y502,MATCH($B21,상담데이터입력!A3:A502,0)),"")) | H21: =IF($B21="","",IFERROR(INDEX(상담데이터입력!BG3:BG502,MATCH($B21,상담데이터입력!A3:A502,0)),"")) | I21: =IF($B21="","",IFERROR(INDEX(상담데이터입력!BI3:BI502,MATCH($B21,상담데이터입력!A3:A502,0)),""))
B22: =IFERROR(INDEX(상담데이터입력!A3:A502,MATCH(15,상담데이터입력!$BJ$3:$BJ$502,0)),"") | C22: =IF($B22="","",IFERROR(INDEX(상담데이터입력!B3:B502,MATCH($B22,상담데이터입력!A3:A502,0)),"")) | D22: =IF($B22="","",IFERROR(INDEX(상담데이터입력!H3:H502,MATCH($B22,상담데이터입력!A3:A502,0)),"")) | E22: =IF($B22="","",IFERROR(INDEX(상담데이터입력!S3:S502,MATCH($B22,상담데이터입력!A3:A502,0)),"")) | F22: =IF($B22="","",IFERROR(INDEX(상담데이터입력!W3:W502,MATCH($B22,상담데이터입력!A3:A502,0)),"")) | G22: =IF($B22="","",IFERROR(INDEX(상담데이터입력!Y3:Y502,MATCH($B22,상담데이터입력!A3:A502,0)),"")) | H22: =IF($B22="","",IFERROR(INDEX(상담데이터입력!BG3:BG502,MATCH($B22,상담데이터입력!A3:A502,0)),"")) | I22: =IF($B22="","",IFERROR(INDEX(상담데이터입력!BI3:BI502,MATCH($B22,상담데이터입력!A3:A502,0)),""))
B23: =IFERROR(INDEX(상담데이터입력!A3:A502,MATCH(16,상담데이터입력!$BJ$3:$BJ$502,0)),"") | C23: =IF($B23="","",IFERROR(INDEX(상담데이터입력!B3:B502,MATCH($B23,상담데이터입력!A3:A502,0)),"")) | D23: =IF($B23="","",IFERROR(INDEX(상담데이터입력!H3:H502,MATCH($B23,상담데이터입력!A3:A502,0)),"")) | E23: =IF($B23="","",IFERROR(INDEX(상담데이터입력!S3:S502,MATCH($B23,상담데이터입력!A3:A502,0)),"")) | F23: =IF($B23="","",IFERROR(INDEX(상담데이터입력!W3:W502,MATCH($B23,상담데이터입력!A3:A502,0)),"")) | G23: =IF($B23="","",IFERROR(INDEX(상담데이터입력!Y3:Y502,MATCH($B23,상담데이터입력!A3:A502,0)),"")) | H23: =IF($B23="","",IFERROR(INDEX(상담데이터입력!BG3:BG502,MATCH($B23,상담데이터입력!A3:A502,0)),"")) | I23: =IF($B23="","",IFERROR(INDEX(상담데이터입력!BI3:BI502,MATCH($B23,상담데이터입력!A3:A502,0)),""))
B24: =IFERROR(INDEX(상담데이터입력!A3:A502,MATCH(17,상담데이터입력!$BJ$3:$BJ$502,0)),"") | C24: =IF($B24="","",IFERROR(INDEX(상담데이터입력!B3:B502,MATCH($B24,상담데이터입력!A3:A502,0)),"")) | D24: =IF($B24="","",IFERROR(INDEX(상담데이터입력!H3:H502,MATCH($B24,상담데이터입력!A3:A502,0)),"")) | E24: =IF($B24="","",IFERROR(INDEX(상담데이터입력!S3:S502,MATCH($B24,상담데이터입력!A3:A502,0)),"")) | F24: =IF($B24="","",IFERROR(INDEX(상담데이터입력!W3:W502,MATCH($B24,상담데이터입력!A3:A502,0)),"")) | G24: =IF($B24="","",IFERROR(INDEX(상담데이터입력!Y3:Y502,MATCH($B24,상담데이터입력!A3:A502,0)),"")) | H24: =IF($B24="","",IFERROR(INDEX(상담데이터입력!BG3:BG502,MATCH($B24,상담데이터입력!A3:A502,0)),"")) | I24: =IF($B24="","",IFERROR(INDEX(상담데이터입력!BI3:BI502,MATCH($B24,상담데이터입력!A3:A502,0)),""))
B25: =IFERROR(INDEX(상담데이터입력!A3:A502,MATCH(18,상담데이터입력!$BJ$3:$BJ$502,0)),"") | C25: =IF($B25="","",IFERROR(INDEX(상담데이터입력!B3:B502,MATCH($B25,상담데이터입력!A3:A502,0)),"")) | D25: =IF($B25="","",IFERROR(INDEX(상담데이터입력!H3:H502,MATCH($B25,상담데이터입력!A3:A502,0)),"")) | E25: =IF($B25="","",IFERROR(INDEX(상담데이터입력!S3:S502,MATCH($B25,상담데이터입력!A3:A502,0)),"")) | F25: =IF($B25="","",IFERROR(INDEX(상담데이터입력!W3:W502,MATCH($B25,상담데이터입력!A3:A502,0)),"")) | G25: =IF($B25="","",IFERROR(INDEX(상담데이터입력!Y3:Y502,MATCH($B25,상담데이터입력!A3:A502,0)),"")) | H25: =IF($B25="","",IFERROR(INDEX(상담데이터입력!BG3:BG502,MATCH($B25,상담데이터입력!A3:A502,0)),"")) | I25: =IF($B25="","",IFERROR(INDEX(상담데이터입력!BI3:BI502,MATCH($B25,상담데이터입력!A3:A502,0)),""))
B26: =IFERROR(INDEX(상담데이터입력!A3:A502,MATCH(19,상담데이터입력!$BJ$3:$BJ$502,0)),"") | C26: =IF($B26="","",IFERROR(INDEX(상담데이터입력!B3:B502,MATCH($B26,상담데이터입력!A3:A502,0)),"")) | D26: =IF($B26="","",IFERROR(INDEX(상담데이터입력!H3:H502,MATCH($B26,상담데이터입력!A3:A502,0)),"")) | E26: =IF($B26="","",IFERROR(INDEX(상담데이터입력!S3:S502,MATCH($B26,상담데이터입력!A3:A502,0)),"")) | F26: =IF($B26="","",IFERROR(INDEX(상담데이터입력!W3:W502,MATCH($B26,상담데이터입력!A3:A502,0)),"")) | G26: =IF($B26="","",IFERROR(INDEX(상담데이터입력!Y3:Y502,MATCH($B26,상담데이터입력!A3:A502,0)),"")) | H26: =IF($B26="","",IFERROR(INDEX(상담데이터입력!BG3:BG502,MATCH($B26,상담데이터입력!A3:A502,0)),"")) | I26: =IF($B26="","",IFERROR(INDEX(상담데이터입력!BI3:BI502,MATCH($B26,상담데이터입력!A3:A502,0)),""))
B27: =IFERROR(INDEX(상담데이터입력!A3:A502,MATCH(20,상담데이터입력!$BJ$3:$BJ$502,0)),"") | C27: =IF($B27="","",IFERROR(INDEX(상담데이터입력!B3:B502,MATCH($B27,상담데이터입력!A3:A502,0)),"")) | D27: =IF($B27="","",IFERROR(INDEX(상담데이터입력!H3:H502,MATCH($B27,상담데이터입력!A3:A502,0)),"")) | E27: =IF($B27="","",IFERROR(INDEX(상담데이터입력!S3:S502,MATCH($B27,상담데이터입력!A3:A502,0)),"")) | F27: =IF($B27="","",IFERROR(INDEX(상담데이터입력!W3:W502,MATCH($B27,상담데이터입력!A3:A502,0)),"")) | G27: =IF($B27="","",IFERROR(INDEX(상담데이터입력!Y3:Y502,MATCH($B27,상담데이터입력!A3:A502,0)),"")) | H27: =IF($B27="","",IFERROR(INDEX(상담데이터입력!BG3:BG502,MATCH($B27,상담데이터입력!A3:A502,0)),"")) | I27: =IF($B27="","",IFERROR(INDEX(상담데이터입력!BI3:BI502,MATCH($B27,상담데이터입력!A3:A502,0)),""))
B28: =IFERROR(INDEX(상담데이터입력!A3:A502,MATCH(21,상담데이터입력!$BJ$3:$BJ$502,0)),"") | C28: =IF($B28="","",IFERROR(INDEX(상담데이터입력!B3:B502,MATCH($B28,상담데이터입력!A3:A502,0)),"")) | D28: =IF($B28="","",IFERROR(INDEX(상담데이터입력!H3:H502,MATCH($B28,상담데이터입력!A3:A502,0)),"")) | E28: =IF($B28="","",IFERROR(INDEX(상담데이터입력!S3:S502,MATCH($B28,상담데이터입력!A3:A502,0)),"")) | F28: =IF($B28="","",IFERROR(INDEX(상담데이터입력!W3:W502,MATCH($B28,상담데이터입력!A3:A502,0)),"")) | G28: =IF($B28="","",IFERROR(INDEX(상담데이터입력!Y3:Y502,MATCH($B28,상담데이터입력!A3:A502,0)),"")) | H28: =IF($B28="","",IFERROR(INDEX(상담데이터입력!BG3:BG502,MATCH($B28,상담데이터입력!A3:A502,0)),"")) | I28: =IF($B28="","",IFERROR(INDEX(상담데이터입력!BI3:BI502,MATCH($B28,상담데이터입력!A3:A502,0)),""))
B29: =IFERROR(INDEX(상담데이터입력!A3:A502,MATCH(22,상담데이터입력!$BJ$3:$BJ$502,0)),"") | C29: =IF($B29="","",IFERROR(INDEX(상담데이터입력!B3:B502,MATCH($B29,상담데이터입력!A3:A502,0)),"")) | D29: =IF($B29="","",IFERROR(INDEX(상담데이터입력!H3:H502,MATCH($B29,상담데이터입력!A3:A502,0)),"")) | E29: =IF($B29="","",IFERROR(INDEX(상담데이터입력!S3:S502,MATCH($B29,상담데이터입력!A3:A502,0)),"")) | F29: =IF($B29="","",IFERROR(INDEX(상담데이터입력!W3:W502,MATCH($B29,상담데이터입력!A3:A502,0)),"")) | G29: =IF($B29="","",IFERROR(INDEX(상담데이터입력!Y3:Y502,MATCH($B29,상담데이터입력!A3:A502,0)),"")) | H29: =IF($B29="","",IFERROR(INDEX(상담데이터입력!BG3:BG502,MATCH($B29,상담데이터입력!A3:A502,0)),"")) | I29: =IF($B29="","",IFERROR(INDEX(상담데이터입력!BI3:BI502,MATCH($B29,상담데이터입력!A3:A502,0)),""))
B30: =IFERROR(INDEX(상담데이터입력!A3:A502,MATCH(23,상담데이터입력!$BJ$3:$BJ$502,0)),"") | C30: =IF($B30="","",IFERROR(INDEX(상담데이터입력!B3:B502,MATCH($B30,상담데이터입력!A3:A502,0)),"")) | D30: =IF($B30="","",IFERROR(INDEX(상담데이터입력!H3:H502,MATCH($B30,상담데이터입력!A3:A502,0)),"")) | E30: =IF($B30="","",IFERROR(INDEX(상담데이터입력!S3:S502,MATCH($B30,상담데이터입력!A3:A502,0)),"")) | F30: =IF($B30="","",IFERROR(INDEX(상담데이터입력!W3:W502,MATCH($B30,상담데이터입력!A3:A502,0)),"")) | G30: =IF($B30="","",IFERROR(INDEX(상담데이터입력!Y3:Y502,MATCH($B30,상담데이터입력!A3:A502,0)),"")) | H30: =IF($B30="","",IFERROR(INDEX(상담데이터입력!BG3:BG502,MATCH($B30,상담데이터입력!A3:A502,0)),"")) | I30: =IF($B30="","",IFERROR(INDEX(상담데이터입력!BI3:BI502,MATCH($B30,상담데이터입력!A3:A502,0)),""))
B31: =IFERROR(INDEX(상담데이터입력!A3:A502,MATCH(24,상담데이터입력!$BJ$3:$BJ$502,0)),"") | C31: =IF($B31="","",IFERROR(INDEX(상담데이터입력!B3:B502,MATCH($B31,상담데이터입력!A3:A502,0)),"")) | D31: =IF($B31="","",IFERROR(INDEX(상담데이터입력!H3:H502,MATCH($B31,상담데이터입력!A3:A502,0)),"")) | E31: =IF($B31="","",IFERROR(INDEX(상담데이터입력!S3:S502,MATCH($B31,상담데이터입력!A3:A502,0)),"")) | F31: =IF($B31="","",IFERROR(INDEX(상담데이터입력!W3:W502,MATCH($B31,상담데이터입력!A3:A502,0)),"")) | G31: =IF($B31="","",IFERROR(INDEX(상담데이터입력!Y3:Y502,MATCH($B31,상담데이터입력!A3:A502,0)),"")) | H31: =IF($B31="","",IFERROR(INDEX(상담데이터입력!BG3:BG502,MATCH($B31,상담데이터입력!A3:A502,0)),"")) | I31: =IF($B31="","",IFERROR(INDEX(상담데이터입력!BI3:BI502,MATCH($B31,상담데이터입력!A3:A502,0)),""))
B32: =IFERROR(INDEX(상담데이터입력!A3:A502,MATCH(25,상담데이터입력!$BJ$3:$BJ$502,0)),"") | C32: =IF($B32="","",IFERROR(INDEX(상담데이터입력!B3:B502,MATCH($B32,상담데이터입력!A3:A502,0)),"")) | D32: =IF($B32="","",IFERROR(INDEX(상담데이터입력!H3:H502,MATCH($B32,상담데이터입력!A3:A502,0)),"")) | E32: =IF($B32="","",IFERROR(INDEX(상담데이터입력!S3:S502,MATCH($B32,상담데이터입력!A3:A502,0)),"")) | F32: =IF($B32="","",IFERROR(INDEX(상담데이터입력!W3:W502,MATCH($B32,상담데이터입력!A3:A502,0)),"")) | G32: =IF($B32="","",IFERROR(INDEX(상담데이터입력!Y3:Y502,MATCH($B32,상담데이터입력!A3:A502,0)),"")) | H32: =IF($B32="","",IFERROR(INDEX(상담데이터입력!BG3:BG502,MATCH($B32,상담데이터입력!A3:A502,0)),"")) | I32: =IF($B32="","",IFERROR(INDEX(상담데이터입력!BI3:BI502,MATCH($B32,상담데이터입력!A3:A502,0)),""))
B33: =IFERROR(INDEX(상담데이터입력!A3:A502,MATCH(26,상담데이터입력!$BJ$3:$BJ$502,0)),"") | C33: =IF($B33="","",IFERROR(INDEX(상담데이터입력!B3:B502,MATCH($B33,상담데이터입력!A3:A502,0)),"")) | D33: =IF($B33="","",IFERROR(INDEX(상담데이터입력!H3:H502,MATCH($B33,상담데이터입력!A3:A502,0)),"")) | E33: =IF($B33="","",IFERROR(INDEX(상담데이터입력!S3:S502,MATCH($B33,상담데이터입력!A3:A502,0)),"")) | F33: =IF($B33="","",IFERROR(INDEX(상담데이터입력!W3:W502,MATCH($B33,상담데이터입력!A3:A502,0)),"")) | G33: =IF($B33="","",IFERROR(INDEX(상담데이터입력!Y3:Y502,MATCH($B33,상담데이터입력!A3:A502,0)),"")) | H33: =IF($B33="","",IFERROR(INDEX(상담데이터입력!BG3:BG502,MATCH($B33,상담데이터입력!A3:A502,0)),"")) | I33: =IF($B33="","",IFERROR(INDEX(상담데이터입력!BI3:BI502,MATCH($B33,상담데이터입력!A3:A502,0)),""))
B34: =IFERROR(INDEX(상담데이터입력!A3:A502,MATCH(27,상담데이터입력!$BJ$3:$BJ$502,0)),"") | C34: =IF($B34="","",IFERROR(INDEX(상담데이터입력!B3:B502,MATCH($B34,상담데이터입력!A3:A502,0)),"")) | D34: =IF($B34="","",IFERROR(INDEX(상담데이터입력!H3:H502,MATCH($B34,상담데이터입력!A3:A502,0)),"")) | E34: =IF($B34="","",IFERROR(INDEX(상담데이터입력!S3:S502,MATCH($B34,상담데이터입력!A3:A502,0)),"")) | F34: =IF($B34="","",IFERROR(INDEX(상담데이터입력!W3:W502,MATCH($B34,상담데이터입력!A3:A502,0)),"")) | G34: =IF($B34="","",IFERROR(INDEX(상담데이터입력!Y3:Y502,MATCH($B34,상담데이터입력!A3:A502,0)),"")) | H34: =IF($B34="","",IFERROR(INDEX(상담데이터입력!BG3:BG502,MATCH($B34,상담데이터입력!A3:A502,0)),"")) | I34: =IF($B34="","",IFERROR(INDEX(상담데이터입력!BI3:BI502,MATCH($B34,상담데이터입력!A3:A502,0)),""))
B35: =IFERROR(INDEX(상담데이터입력!A3:A502,MATCH(28,상담데이터입력!$BJ$3:$BJ$502,0)),"") | C35: =IF($B35="","",IFERROR(INDEX(상담데이터입력!B3:B502,MATCH($B35,상담데이터입력!A3:A502,0)),"")) | D35: =IF($B35="","",IFERROR(INDEX(상담데이터입력!H3:H502,MATCH($B35,상담데이터입력!A3:A502,0)),"")) | E35: =IF($B35="","",IFERROR(INDEX(상담데이터입력!S3:S502,MATCH($B35,상담데이터입력!A3:A502,0)),"")) | F35: =IF($B35="","",IFERROR(INDEX(상담데이터입력!W3:W502,MATCH($B35,상담데이터입력!A3:A502,0)),"")) | G35: =IF($B35="","",IFERROR(INDEX(상담데이터입력!Y3:Y502,MATCH($B35,상담데이터입력!A3:A502,0)),"")) | H35: =IF($B35="","",IFERROR(INDEX(상담데이터입력!BG3:BG502,MATCH($B35,상담데이터입력!A3:A502,0)),"")) | I35: =IF($B35="","",IFERROR(INDEX(상담데이터입력!BI3:BI502,MATCH($B35,상담데이터입력!A3:A502,0)),""))
B36: =IFERROR(INDEX(상담데이터입력!A3:A502,MATCH(29,상담데이터입력!$BJ$3:$BJ$502,0)),"") | C36: =IF($B36="","",IFERROR(INDEX(상담데이터입력!B3:B502,MATCH($B36,상담데이터입력!A3:A502,0)),"")) | D36: =IF($B36="","",IFERROR(INDEX(상담데이터입력!H3:H502,MATCH($B36,상담데이터입력!A3:A502,0)),"")) | E36: =IF($B36="","",IFERROR(INDEX(상담데이터입력!S3:S502,MATCH($B36,상담데이터입력!A3:A502,0)),"")) | F36: =IF($B36="","",IFERROR(INDEX(상담데이터입력!W3:W502,MATCH($B36,상담데이터입력!A3:A502,0)),"")) | G36: =IF($B36="","",IFERROR(INDEX(상담데이터입력!Y3:Y502,MATCH($B36,상담데이터입력!A3:A502,0)),"")) | H36: =IF($B36="","",IFERROR(INDEX(상담데이터입력!BG3:BG502,MATCH($B36,상담데이터입력!A3:A502,0)),"")) | I36: =IF($B36="","",IFERROR(INDEX(상담데이터입력!BI3:BI502,MATCH($B36,상담데이터입력!A3:A502,0)),""))
B37: =IFERROR(INDEX(상담데이터입력!A3:A502,MATCH(30,상담데이터입력!$BJ$3:$BJ$502,0)),"") | C37: =IF($B37="","",IFERROR(INDEX(상담데이터입력!B3:B502,MATCH($B37,상담데이터입력!A3:A502,0)),"")) | D37: =IF($B37="","",IFERROR(INDEX(상담데이터입력!H3:H502,MATCH($B37,상담데이터입력!A3:A502,0)),"")) | E37: =IF($B37="","",IFERROR(INDEX(상담데이터입력!S3:S502,MATCH($B37,상담데이터입력!A3:A502,0)),"")) | F37: =IF($B37="","",IFERROR(INDEX(상담데이터입력!W3:W502,MATCH($B37,상담데이터입력!A3:A502,0)),"")) | G37: =IF($B37="","",IFERROR(INDEX(상담데이터입력!Y3:Y502,MATCH($B37,상담데이터입력!A3:A502,0)),"")) | H37: =IF($B37="","",IFERROR(INDEX(상담데이터입력!BG3:BG502,MATCH($B37,상담데이터입력!A3:A502,0)),"")) | I37: =IF($B37="","",IFERROR(INDEX(상담데이터입력!BI3:BI502,MATCH($B37,상담데이터입력!A3:A502,0)),""))
B38: =IFERROR(INDEX(상담데이터입력!A3:A502,MATCH(31,상담데이터입력!$BJ$3:$BJ$502,0)),"") | C38: =IF($B38="","",IFERROR(INDEX(상담데이터입력!B3:B502,MATCH($B38,상담데이터입력!A3:A502,0)),"")) | D38: =IF($B38="","",IFERROR(INDEX(상담데이터입력!H3:H502,MATCH($B38,상담데이터입력!A3:A502,0)),"")) | E38: =IF($B38="","",IFERROR(INDEX(상담데이터입력!S3:S502,MATCH($B38,상담데이터입력!A3:A502,0)),"")) | F38: =IF($B38="","",IFERROR(INDEX(상담데이터입력!W3:W502,MATCH($B38,상담데이터입력!A3:A502,0)),"")) | G38: =IF($B38="","",IFERROR(INDEX(상담데이터입력!Y3:Y502,MATCH($B38,상담데이터입력!A3:A502,0)),"")) | H38: =IF($B38="","",IFERROR(INDEX(상담데이터입력!BG3:BG502,MATCH($B38,상담데이터입력!A3:A502,0)),"")) | I38: =IF($B38="","",IFERROR(INDEX(상담데이터입력!BI3:BI502,MATCH($B38,상담데이터입력!A3:A502,0)),""))
B39: =IFERROR(INDEX(상담데이터입력!A3:A502,MATCH(32,상담데이터입력!$BJ$3:$BJ$502,0)),"") | C39: =IF($B39="","",IFERROR(INDEX(상담데이터입력!B3:B502,MATCH($B39,상담데이터입력!A3:A502,0)),"")) | D39: =IF($B39="","",IFERROR(INDEX(상담데이터입력!H3:H502,MATCH($B39,상담데이터입력!A3:A502,0)),"")) | E39: =IF($B39="","",IFERROR(INDEX(상담데이터입력!S3:S502,MATCH($B39,상담데이터입력!A3:A502,0)),"")) | F39: =IF($B39="","",IFERROR(INDEX(상담데이터입력!W3:W502,MATCH($B39,상담데이터입력!A3:A502,0)),"")) | G39: =IF($B39="","",IFERROR(INDEX(상담데이터입력!Y3:Y502,MATCH($B39,상담데이터입력!A3:A502,0)),"")) | H39: =IF($B39="","",IFERROR(INDEX(상담데이터입력!BG3:BG502,MATCH($B39,상담데이터입력!A3:A502,0)),"")) | I39: =IF($B39="","",IFERROR(INDEX(상담데이터입력!BI3:BI502,MATCH($B39,상담데이터입력!A3:A502,0)),""))
B40: =IFERROR(INDEX(상담데이터입력!A3:A502,MATCH(33,상담데이터입력!$BJ$3:$BJ$502,0)),"") | C40: =IF($B40="","",IFERROR(INDEX(상담데이터입력!B3:B502,MATCH($B40,상담데이터입력!A3:A502,0)),"")) | D40: =IF($B40="","",IFERROR(INDEX(상담데이터입력!H3:H502,MATCH($B40,상담데이터입력!A3:A502,0)),"")) | E40: =IF($B40="","",IFERROR(INDEX(상담데이터입력!S3:S502,MATCH($B40,상담데이터입력!A3:A502,0)),"")) | F40: =IF($B40="","",IFERROR(INDEX(상담데이터입력!W3:W502,MATCH($B40,상담데이터입력!A3:A502,0)),"")) | G40: =IF($B40="","",IFERROR(INDEX(상담데이터입력!Y3:Y502,MATCH($B40,상담데이터입력!A3:A502,0)),"")) | H40: =IF($B40="","",IFERROR(INDEX(상담데이터입력!BG3:BG502,MATCH($B40,상담데이터입력!A3:A502,0)),"")) | I40: =IF($B40="","",IFERROR(INDEX(상담데이터입력!BI3:BI502,MATCH($B40,상담데이터입력!A3:A502,0)),""))
B41: =IFERROR(INDEX(상담데이터입력!A3:A502,MATCH(34,상담데이터입력!$BJ$3:$BJ$502,0)),"") | C41: =IF($B41="","",IFERROR(INDEX(상담데이터입력!B3:B502,MATCH($B41,상담데이터입력!A3:A502,0)),"")) | D41: =IF($B41="","",IFERROR(INDEX(상담데이터입력!H3:H502,MATCH($B41,상담데이터입력!A3:A502,0)),"")) | E41: =IF($B41="","",IFERROR(INDEX(상담데이터입력!S3:S502,MATCH($B41,상담데이터입력!A3:A502,0)),"")) | F41: =IF($B41="","",IFERROR(INDEX(상담데이터입력!W3:W502,MATCH($B41,상담데이터입력!A3:A502,0)),"")) | G41: =IF($B41="","",IFERROR(INDEX(상담데이터입력!Y3:Y502,MATCH($B41,상담데이터입력!A3:A502,0)),"")) | H41: =IF($B41="","",IFERROR(INDEX(상담데이터입력!BG3:BG502,MATCH($B41,상담데이터입력!A3:A502,0)),"")) | I41: =IF($B41="","",IFERROR(INDEX(상담데이터입력!BI3:BI502,MATCH($B41,상담데이터입력!A3:A502,0)),""))
B42: =IFERROR(INDEX(상담데이터입력!A3:A502,MATCH(35,상담데이터입력!$BJ$3:$BJ$502,0)),"") | C42: =IF($B42="","",IFERROR(INDEX(상담데이터입력!B3:B502,MATCH($B42,상담데이터입력!A3:A502,0)),"")) | D42: =IF($B42="","",IFERROR(INDEX(상담데이터입력!H3:H502,MATCH($B42,상담데이터입력!A3:A502,0)),"")) | E42: =IF($B42="","",IFERROR(INDEX(상담데이터입력!S3:S502,MATCH($B42,상담데이터입력!A3:A502,0)),"")) | F42: =IF($B42="","",IFERROR(INDEX(상담데이터입력!W3:W502,MATCH($B42,상담데이터입력!A3:A502,0)),"")) | G42: =IF($B42="","",IFERROR(INDEX(상담데이터입력!Y3:Y502,MATCH($B42,상담데이터입력!A3:A502,0)),"")) | H42: =IF($B42="","",IFERROR(INDEX(상담데이터입력!BG3:BG502,MATCH($B42,상담데이터입력!A3:A502,0)),"")) | I42: =IF($B42="","",IFERROR(INDEX(상담데이터입력!BI3:BI502,MATCH($B42,상담데이터입력!A3:A502,0)),""))
B43: =IFERROR(INDEX(상담데이터입력!A3:A502,MATCH(36,상담데이터입력!$BJ$3:$BJ$502,0)),"") | C43: =IF($B43="","",IFERROR(INDEX(상담데이터입력!B3:B502,MATCH($B43,상담데이터입력!A3:A502,0)),"")) | D43: =IF($B43="","",IFERROR(INDEX(상담데이터입력!H3:H502,MATCH($B43,상담데이터입력!A3:A502,0)),"")) | E43: =IF($B43="","",IFERROR(INDEX(상담데이터입력!S3:S502,MATCH($B43,상담데이터입력!A3:A502,0)),"")) | F43: =IF($B43="","",IFERROR(INDEX(상담데이터입력!W3:W502,MATCH($B43,상담데이터입력!A3:A502,0)),"")) | G43: =IF($B43="","",IFERROR(INDEX(상담데이터입력!Y3:Y502,MATCH($B43,상담데이터입력!A3:A502,0)),"")) | H43: =IF($B43="","",IFERROR(INDEX(상담데이터입력!BG3:BG502,MATCH($B43,상담데이터입력!A3:A502,0)),"")) | I43: =IF($B43="","",IFERROR(INDEX(상담데이터입력!BI3:BI502,MATCH($B43,상담데이터입력!A3:A502,0)),""))
...

Sheet 상담데이터입력
A1: ◆ 관리·기본 | E1: PART 1 · 인적사항 | P1: PART 1 · 어학 | V1: PART 2 · 동기·목표 | Z1: PART 3 · 비자·경험 | AD1: PART 4 · 학업·재정 | AT1: PART 5 · 성향·K컬처 | BE1: PART 6 | BF1: 노션 / 비고 | BH1: 자동
A2: 이름(한국어) | B2: 이름(몽골어) | C2: 등록일 | D2: 반 | E2: 생년월일 | F2: 나이(자동) | G2: 성별 | H2: 연락처 | I2: SNS_ID | J2: 이메일 | K2: 거주지역 | L2: 최종학력 | M2: 보호자명 | N2: 보호자관계 | O2: 보호자연락처 | P2: TOPIK급수 | Q2: TOPIK점수 | R2: 기타인증서 | S2: 한국어수준 | T2: 영어(점수/회화) | U2: 학습경로 | V2: 핵심비전 | W2: TOPIK목표 | X2: TOPIK목표기한 | Y2: 대학진학시기 | Z2: 한국방문경험 | AA2: 비자신청이력 | AB2: 거절비자종류 | AC2: 가족한국체류 | AD2: 희망진학과정 | AE2: 희망진학지역 | AF2: 현재직업 | AG2: 학습가능시간 | AH2: 목표달성시기 | AI2: 졸업후진로 | AJ2: 핵심가치관 | AK2: 지망대학1순위 | AL2: 지망대학2순위 | AM2: 지망대학3순위 | AN2: 지망전공1순위 | AO2: 지망전공2순위 | AP2: 지망전공3순위 | AQ2: 유학예산 | AR2: 학비조달주체 | AS2: 가족지지 | AT2: 성격유형 | AU2: 학습_집중 | AV2: 학습_방식 | AW2: 학습_태도 | AX2: 대표강점 | AY2: 관심K분야 | AZ2: KPOP댄스희망 | BA2: 보컬트레이닝 | BB2: 연기체험 | BC2: K뷰티메이크업 | BD2: 영어수업관심 | BE2: 인지채널 | BF2: 📝자유서술→노션 | BG2: 비고 | BH2: 학생ID | BI2: ⚠위험신호(자동) | BJ2: 반조회순번(숨김)
F3: =IF($E3="","",INT((TODAY()-$E3)/365.25)) | BH3: =IF($A3="","","SYNK-"&TEXT(ROW()-2,"000")) | BI3: =IF(A3="","",TRIM(IF(AA3="거절","⚠비자거절 ","")&IF(AS3="설득필요","⚠가족설득필요 ","")&IF(AND(W3="5~6급",OR(S3="완전초보",S3="기초")),"⚠목표-수준괴리 ","")&IF(AND(AQ3="빠듯함",AS3="설득필요"),"⚠재정리스크 ",""))) | BJ3: =IF(AND($A3<>"",$D3=반별조회!$C$5),COUNTIFS($A$3:$A3,"<>",$D$3:$D3,반별조회!$C$5),"")
F4: =IF($E4="","",INT((TODAY()-$E4)/365.25)) | BH4: =IF($A4="","","SYNK-"&TEXT(ROW()-2,"000")) | BI4: =IF(A4="","",TRIM(IF(AA4="거절","⚠비자거절 ","")&IF(AS4="설득필요","⚠가족설득필요 ","")&IF(AND(W4="5~6급",OR(S4="완전초보",S4="기초")),"⚠목표-수준괴리 ","")&IF(AND(AQ4="빠듯함",AS4="설득필요"),"⚠재정리스크 ",""))) | BJ4: =IF(AND($A4<>"",$D4=반별조회!$C$5),COUNTIFS($A$3:$A4,"<>",$D$3:$D4,반별조회!$C$5),"")
F5: =IF($E5="","",INT((TODAY()-$E5)/365.25)) | BH5: =IF($A5="","","SYNK-"&TEXT(ROW()-2,"000")) | BI5: =IF(A5="","",TRIM(IF(AA5="거절","⚠비자거절 ","")&IF(AS5="설득필요","⚠가족설득필요 ","")&IF(AND(W5="5~6급",OR(S5="완전초보",S5="기초")),"⚠목표-수준괴리 ","")&IF(AND(AQ5="빠듯함",AS5="설득필요"),"⚠재정리스크 ",""))) | BJ5: =IF(AND($A5<>"",$D5=반별조회!$C$5),COUNTIFS($A$3:$A5,"<>",$D$3:$D5,반별조회!$C$5),"")
F6: =IF($E6="","",INT((TODAY()-$E6)/365.25)) | BH6: =IF($A6="","","SYNK-"&TEXT(ROW()-2,"000")) | BI6: =IF(A6="","",TRIM(IF(AA6="거절","⚠비자거절 ","")&IF(AS6="설득필요","⚠가족설득필요 ","")&IF(AND(W6="5~6급",OR(S6="완전초보",S6="기초")),"⚠목표-수준괴리 ","")&IF(AND(AQ6="빠듯함",AS6="설득필요"),"⚠재정리스크 ",""))) | BJ6: =IF(AND($A6<>"",$D6=반별조회!$C$5),COUNTIFS($A$3:$A6,"<>",$D$3:$D6,반별조회!$C$5),"")
F7: =IF($E7="","",INT((TODAY()-$E7)/365.25)) | BH7: =IF($A7="","","SYNK-"&TEXT(ROW()-2,"000")) | BI7: =IF(A7="","",TRIM(IF(AA7="거절","⚠비자거절 ","")&IF(AS7="설득필요","⚠가족설득필요 ","")&IF(AND(W7="5~6급",OR(S7="완전초보",S7="기초")),"⚠목표-수준괴리 ","")&IF(AND(AQ7="빠듯함",AS7="설득필요"),"⚠재정리스크 ",""))) | BJ7: =IF(AND($A7<>"",$D7=반별조회!$C$5),COUNTIFS($A$3:$A7,"<>",$D$3:$D7,반별조회!$C$5),"")
F8: =IF($E8="","",INT((TODAY()-$E8)/365.25)) | BH8: =IF($A8="","","SYNK-"&TEXT(ROW()-2,"000")) | BI8: =IF(A8="","",TRIM(IF(AA8="거절","⚠비자거절 ","")&IF(AS8="설득필요","⚠가족설득필요 ","")&IF(AND(W8="5~6급",OR(S8="완전초보",S8="기초")),"⚠목표-수준괴리 ","")&IF(AND(AQ8="빠듯함",AS8="설득필요"),"⚠재정리스크 ",""))) | BJ8: =IF(AND($A8<>"",$D8=반별조회!$C$5),COUNTIFS($A$3:$A8,"<>",$D$3:$D8,반별조회!$C$5),"")
F9: =IF($E9="","",INT((TODAY()-$E9)/365.25)) | BH9: =IF($A9="","","SYNK-"&TEXT(ROW()-2,"000")) | BI9: =IF(A9="","",TRIM(IF(AA9="거절","⚠비자거절 ","")&IF(AS9="설득필요","⚠가족설득필요 ","")&IF(AND(W9="5~6급",OR(S9="완전초보",S9="기초")),"⚠목표-수준괴리 ","")&IF(AND(AQ9="빠듯함",AS9="설득필요"),"⚠재정리스크 ",""))) | BJ9: =IF(AND($A9<>"",$D9=반별조회!$C$5),COUNTIFS($A$3:$A9,"<>",$D$3:$D9,반별조회!$C$5),"")
F10: =IF($E10="","",INT((TODAY()-$E10)/365.25)) | BH10: =IF($A10="","","SYNK-"&TEXT(ROW()-2,"000")) | BI10: =IF(A10="","",TRIM(IF(AA10="거절","⚠비자거절 ","")&IF(AS10="설득필요","⚠가족설득필요 ","")&IF(AND(W10="5~6급",OR(S10="완전초보",S10="기초")),"⚠목표-수준괴리 ","")&IF(AND(AQ10="빠듯함",AS10="설득필요"),"⚠재정리스크 ",""))) | BJ10: =IF(AND($A10<>"",$D10=반별조회!$C$5),COUNTIFS($A$3:$A10,"<>",$D$3:$D10,반별조회!$C$5),"")
F11: =IF($E11="","",INT((TODAY()-$E11)/365.25)) | BH11: =IF($A11="","","SYNK-"&TEXT(ROW()-2,"000")) | BI11: =IF(A11="","",TRIM(IF(AA11="거절","⚠비자거절 ","")&IF(AS11="설득필요","⚠가족설득필요 ","")&IF(AND(W11="5~6급",OR(S11="완전초보",S11="기초")),"⚠목표-수준괴리 ","")&IF(AND(AQ11="빠듯함",AS11="설득필요"),"⚠재정리스크 ",""))) | BJ11: =IF(AND($A11<>"",$D11=반별조회!$C$5),COUNTIFS($A$3:$A11,"<>",$D$3:$D11,반별조회!$C$5),"")
F12: =IF($E12="","",INT((TODAY()-$E12)/365.25)) | BH12: =IF($A12="","","SYNK-"&TEXT(ROW()-2,"000")) | BI12: =IF(A12="","",TRIM(IF(AA12="거절","⚠비자거절 ","")&IF(AS12="설득필요","⚠가족설득필요 ","")&IF(AND(W12="5~6급",OR(S12="완전초보",S12="기초")),"⚠목표-수준괴리 ","")&IF(AND(AQ12="빠듯함",AS12="설득필요"),"⚠재정리스크 ",""))) | BJ12: =IF(AND($A12<>"",$D12=반별조회!$C$5),COUNTIFS($A$3:$A12,"<>",$D$3:$D12,반별조회!$C$5),"")
F13: =IF($E13="","",INT((TODAY()-$E13)/365.25)) | BH13: =IF($A13="","","SYNK-"&TEXT(ROW()-2,"000")) | BI13: =IF(A13="","",TRIM(IF(AA13="거절","⚠비자거절 ","")&IF(AS13="설득필요","⚠가족설득필요 ","")&IF(AND(W13="5~6급",OR(S13="완전초보",S13="기초")),"⚠목표-수준괴리 ","")&IF(AND(AQ13="빠듯함",AS13="설득필요"),"⚠재정리스크 ",""))) | BJ13: =IF(AND($A13<>"",$D13=반별조회!$C$5),COUNTIFS($A$3:$A13,"<>",$D$3:$D13,반별조회!$C$5),"")
F14: =IF($E14="","",INT((TODAY()-$E14)/365.25)) | BH14: =IF($A14="","","SYNK-"&TEXT(ROW()-2,"000")) | BI14: =IF(A14="","",TRIM(IF(AA14="거절","⚠비자거절 ","")&IF(AS14="설득필요","⚠가족설득필요 ","")&IF(AND(W14="5~6급",OR(S14="완전초보",S14="기초")),"⚠목표-수준괴리 ","")&IF(AND(AQ14="빠듯함",AS14="설득필요"),"⚠재정리스크 ",""))) | BJ14: =IF(AND($A14<>"",$D14=반별조회!$C$5),COUNTIFS($A$3:$A14,"<>",$D$3:$D14,반별조회!$C$5),"")
... F502: =IF($E502="","",INT((TODAY()-$E502)/365.25)) | BH502: =IF($A502="","","SYNK-"&TEXT(ROW()-2,"000")) | BI502: =IF(A502="","",TRIM(IF(AA502="거절","⚠비자거절 ","")&IF(AS502="설득필요","⚠가족설득필요 ","")&IF(AND(W502="5~6급",OR(S502="완전초보",S502="기초")),"⚠목표-수준괴리 ","")&IF(AND(AQ502="빠듯함",AS502="설득필요"),"⚠재정리스크 ",""))) | BJ502: =IF(AND($A502<>"",$D502=반별조회!$C$5),COUNTIFS($A$3:$A502,"<>",$D$3:$D502,반별조회!$C$5),"")

Sheet 수강납입
A1: SYNK 수강 · 납입 관리
A2: ① 이름 선택 → ② 초록칸(수강료·기간·최근납입일) 입력 → 끝. 나머지는 자동. | 날짜는 2026-07-05 형식
A3: 🔴 예정일 지남(미납) = 빨강 자동표시 | 🟡 7일 이내 납입임박 = 노랑
A4: 학생ID (자동) | B4: 이름(한) ← 선택 | C4: 반 (자동) | D4: 한국어수준 (자동) | E4: 수강료(MNT) ★입력 | F4: 수강기간 ★입력 | G4: 최근납입일 ★입력 | H4: 퇴소일 (비우면 재원중) | I4: 퇴소사유 | J4: 다음납입예정 (자동) | K4: 재원상태 (자동)
A5: =IF($B5="","",IFERROR(INDEX(상담데이터입력!$BH$3:$BH$502,MATCH($B5,상담데이터입력!$A$3:$A$502,0)),"")) | C5: =IF($B5="","",IFERROR(INDEX(상담데이터입력!$D$3:$D$502,MATCH($B5,상담데이터입력!$A$3:$A$502,0)),"")) | D5: =IF($B5="","",IFERROR(INDEX(상담데이터입력!$S$3:$S$502,MATCH($B5,상담데이터입력!$A$3:$A$502,0)),"")) | J5: =IF(OR($G5="",$F5=""),"",EDATE($G5,IF($F5="1개월",1,IF($F5="3개월",3,IF($F5="6개월",6,0))))) | K5: =IF($B5="","",IF($H5="","재원중","퇴소"))
A6: =IF($B6="","",IFERROR(INDEX(상담데이터입력!$BH$3:$BH$502,MATCH($B6,상담데이터입력!$A$3:$A$502,0)),"")) | C6: =IF($B6="","",IFERROR(INDEX(상담데이터입력!$D$3:$D$502,MATCH($B6,상담데이터입력!$A$3:$A$502,0)),"")) | D6: =IF($B6="","",IFERROR(INDEX(상담데이터입력!$S$3:$S$502,MATCH($B6,상담데이터입력!$A$3:$A$502,0)),"")) | J6: =IF(OR($G6="",$F6=""),"",EDATE($G6,IF($F6="1개월",1,IF($F6="3개월",3,IF($F6="6개월",6,0))))) | K6: =IF($B6="","",IF($H6="","재원중","퇴소"))
A7: =IF($B7="","",IFERROR(INDEX(상담데이터입력!$BH$3:$BH$502,MATCH($B7,상담데이터입력!$A$3:$A$502,0)),"")) | C7: =IF($B7="","",IFERROR(INDEX(상담데이터입력!$D$3:$D$502,MATCH($B7,상담데이터입력!$A$3:$A$502,0)),"")) | D7: =IF($B7="","",IFERROR(INDEX(상담데이터입력!$S$3:$S$502,MATCH($B7,상담데이터입력!$A$3:$A$502,0)),"")) | J7: =IF(OR($G7="",$F7=""),"",EDATE($G7,IF($F7="1개월",1,IF($F7="3개월",3,IF($F7="6개월",6,0))))) | K7: =IF($B7="","",IF($H7="","재원중","퇴소"))
A8: =IF($B8="","",IFERROR(INDEX(상담데이터입력!$BH$3:$BH$502,MATCH($B8,상담데이터입력!$A$3:$A$502,0)),"")) | C8: =IF($B8="","",IFERROR(INDEX(상담데이터입력!$D$3:$D$502,MATCH($B8,상담데이터입력!$A$3:$A$502,0)),"")) | D8: =IF($B8="","",IFERROR(INDEX(상담데이터입력!$S$3:$S$502,MATCH($B8,상담데이터입력!$A$3:$A$502,0)),"")) | J8: =IF(OR($G8="",$F8=""),"",EDATE($G8,IF($F8="1개월",1,IF($F8="3개월",3,IF($F8="6개월",6,0))))) | K8: =IF($B8="","",IF($H8="","재원중","퇴소"))
A9: =IF($B9="","",IFERROR(INDEX(상담데이터입력!$BH$3:$BH$502,MATCH($B9,상담데이터입력!$A$3:$A$502,0)),"")) | C9: =IF($B9="","",IFERROR(INDEX(상담데이터입력!$D$3:$D$502,MATCH($B9,상담데이터입력!$A$3:$A$502,0)),"")) | D9: =IF($B9="","",IFERROR(INDEX(상담데이터입력!$S$3:$S$502,MATCH($B9,상담데이터입력!$A$3:$A$502,0)),"")) | J9: =IF(OR($G9="",$F9=""),"",EDATE($G9,IF($F9="1개월",1,IF($F9="3개월",3,IF($F9="6개월",6,0))))) | K9: =IF($B9="","",IF($H9="","재원중","퇴소"))
A10: =IF($B10="","",IFERROR(INDEX(상담데이터입력!$BH$3:$BH$502,MATCH($B10,상담데이터입력!$A$3:$A$502,0)),"")) | C10: =IF($B10="","",IFERROR(INDEX(상담데이터입력!$D$3:$D$502,MATCH($B10,상담데이터입력!$A$3:$A$502,0)),"")) | D10: =IF($B10="","",IFERROR(INDEX(상담데이터입력!$S$3:$S$502,MATCH($B10,상담데이터입력!$A$3:$A$502,0)),"")) | J10: =IF(OR($G10="",$F10=""),"",EDATE($G10,IF($F10="1개월",1,IF($F10="3개월",3,IF($F10="6개월",6,0))))) | K10: =IF($B10="","",IF($H10="","재원중","퇴소"))
A11: =IF($B11="","",IFERROR(INDEX(상담데이터입력!$BH$3:$BH$502,MATCH($B11,상담데이터입력!$A$3:$A$502,0)),"")) | C11: =IF($B11="","",IFERROR(INDEX(상담데이터입력!$D$3:$D$502,MATCH($B11,상담데이터입력!$A$3:$A$502,0)),"")) | D11: =IF($B11="","",IFERROR(INDEX(상담데이터입력!$S$3:$S$502,MATCH($B11,상담데이터입력!$A$3:$A$502,0)),"")) | J11: =IF(OR($G11="",$F11=""),"",EDATE($G11,IF($F11="1개월",1,IF($F11="3개월",3,IF($F11="6개월",6,0))))) | K11: =IF($B11="","",IF($H11="","재원중","퇴소"))
A12: =IF($B12="","",IFERROR(INDEX(상담데이터입력!$BH$3:$BH$502,MATCH($B12,상담데이터입력!$A$3:$A$502,0)),"")) | C12: =IF($B12="","",IFERROR(INDEX(상담데이터입력!$D$3:$D$502,MATCH($B12,상담데이터입력!$A$3:$A$502,0)),"")) | D12: =IF($B12="","",IFERROR(INDEX(상담데이터입력!$S$3:$S$502,MATCH($B12,상담데이터입력!$A$3:$A$502,0)),"")) | J12: =IF(OR($G12="",$F12=""),"",EDATE($G12,IF($F12="1개월",1,IF($F12="3개월",3,IF($F12="6개월",6,0))))) | K12: =IF($B12="","",IF($H12="","재원중","퇴소"))
A13: =IF($B13="","",IFERROR(INDEX(상담데이터입력!$BH$3:$BH$502,MATCH($B13,상담데이터입력!$A$3:$A$502,0)),"")) | C13: =IF($B13="","",IFERROR(INDEX(상담데이터입력!$D$3:$D$502,MATCH($B13,상담데이터입력!$A$3:$A$502,0)),"")) | D13: =IF($B13="","",IFERROR(INDEX(상담데이터입력!$S$3:$S$502,MATCH($B13,상담데이터입력!$A$3:$A$502,0)),"")) | J13: =IF(OR($G13="",$F13=""),"",EDATE($G13,IF($F13="1개월",1,IF($F13="3개월",3,IF($F13="6개월",6,0))))) | K13: =IF($B13="","",IF($H13="","재원중","퇴소"))
A14: =IF($B14="","",IFERROR(INDEX(상담데이터입력!$BH$3:$BH$502,MATCH($B14,상담데이터입력!$A$3:$A$502,0)),"")) | C14: =IF($B14="","",IFERROR(INDEX(상담데이터입력!$D$3:$D$502,MATCH($B14,상담데이터입력!$A$3:$A$502,0)),"")) | D14: =IF($B14="","",IFERROR(INDEX(상담데이터입력!$S$3:$S$502,MATCH($B14,상담데이터입력!$A$3:$A$502,0)),"")) | J14: =IF(OR($G14="",$F14=""),"",EDATE($G14,IF($F14="1개월",1,IF($F14="3개월",3,IF($F14="6개월",6,0))))) | K14: =IF($B14="","",IF($H14="","재원중","퇴소"))
A15: =IF($B15="","",IFERROR(INDEX(상담데이터입력!$BH$3:$BH$502,MATCH($B15,상담데이터입력!$A$3:$A$502,0)),"")) | C15: =IF($B15="","",IFERROR(INDEX(상담데이터입력!$D$3:$D$502,MATCH($B15,상담데이터입력!$A$3:$A$502,0)),"")) | D15: =IF($B15="","",IFERROR(INDEX(상담데이터입력!$S$3:$S$502,MATCH($B15,상담데이터입력!$A$3:$A$502,0)),"")) | J15: =IF(OR($G15="",$F15=""),"",EDATE($G15,IF($F15="1개월",1,IF($F15="3개월",3,IF($F15="6개월",6,0))))) | K15: =IF($B15="","",IF($H15="","재원중","퇴소"))
A16: =IF($B16="","",IFERROR(INDEX(상담데이터입력!$BH$3:$BH$502,MATCH($B16,상담데이터입력!$A$3:$A$502,0)),"")) | C16: =IF($B16="","",IFERROR(INDEX(상담데이터입력!$D$3:$D$502,MATCH($B16,상담데이터입력!$A$3:$A$502,0)),"")) | D16: =IF($B16="","",IFERROR(INDEX(상담데이터입력!$S$3:$S$502,MATCH($B16,상담데이터입력!$A$3:$A$502,0)),"")) | J16: =IF(OR($G16="",$F16=""),"",EDATE($G16,IF($F16="1개월",1,IF($F16="3개월",3,IF($F16="6개월",6,0))))) | K16: =IF($B16="","",IF($H16="","재원중","퇴소"))
... A504: =IF($B504="","",IFERROR(INDEX(상담데이터입력!$BH$3:$BH$502,MATCH($B504,상담데이터입력!$A$3:$A$502,0)),"")) | C504: =IF($B504="","",IFERROR(INDEX(상담데이터입력!$D$3:$D$502,MATCH($B504,상담데이터입력!$A$3:$A$502,0)),"")) | D504: =IF($B504="","",IFERROR(INDEX(상담데이터입력!$S$3:$S$502,MATCH($B504,상담데이터입력!$A$3:$A$502,0)),"")) | J504: =IF(OR($G504="",$F504=""),"",EDATE($G504,IF($F504="1개월",1,IF($F504="3개월",3,IF($F504="6개월",6,0))))) | K504: =IF($B504="","",IF($H504="","재원중","퇴소"))

Sheet 반설정
A1: 🏫 반 · 설정 (반명 수정은 여기 한 곳만)
A3: 반명 | B3: 유형 | C3: 시작시간 | D3: 정원 | F3: ※ 이 표가 상담시트 드롭다운·대시보드 여석·(이관 후) 앱 schedule의 단일 원천입니다.
A4: 정규반1 | B4: 평일 | C4: 11:00 | D4: 20
A5: 정규반2 | B5: 평일 | C5: 14:00 | D5: 20
A6: 정규반3 | B6: 평일 | C6: 15:30 | D6: 20
A7: 정규반4 | B7: 평일 | C7: 18:00 | D7: 20
A8: 집중반1 | B8: 평일 | C8: 11:00 | D8: 10
A9: 집중반2 | B9: 평일 | C9: 11:00 | D9: 10
A10: 집중반3 | B10: 평일 | C10: 14:00 | D10: 10
A11: 집중반4 | B11: 평일 | C11: 15:30 | D11: 10
A12: 집중반5 | B12: 평일 | C12: 18:00 | D12: 10
A13: 집중반6 | B13: 평일 | C13: 18:00 | D13: 10
A14: 주말정규반1 | B14: 주말 | C14: 11:00 | D14: 20
A15: 주말정규반2 | B15: 주말 | C15: 15:30 | D15: 20
... A18: 주말집중반3 | B18: 주말 | C18: 15:30 | D18: 10
